{
 "cells": [
  {
   "cell_type": "code",
   "execution_count": 1,
   "metadata": {},
   "outputs": [
    {
     "ename": "ConfigNotFoundError",
     "evalue": "Error: No great_expectations directory was found here!\n    - Please check that you are in the correct directory or have specified the correct directory.\n    - If you have never run Great Expectations in this project, please run `great_expectations init` to get started.\n",
     "output_type": "error",
     "traceback": [
      "\u001b[0;31m---------------------------------------------------------------------------\u001b[0m",
      "\u001b[0;31mConfigNotFoundError\u001b[0m                       Traceback (most recent call last)",
      "\u001b[0;32m/tmp/ipykernel_38715/3237696779.py\u001b[0m in \u001b[0;36m<module>\u001b[0;34m\u001b[0m\n\u001b[1;32m      1\u001b[0m \u001b[0;32mimport\u001b[0m \u001b[0mgreat_expectations\u001b[0m \u001b[0;32mas\u001b[0m \u001b[0mge\u001b[0m\u001b[0;34m\u001b[0m\u001b[0;34m\u001b[0m\u001b[0m\n\u001b[0;32m----> 2\u001b[0;31m \u001b[0mdata\u001b[0m  \u001b[0;34m=\u001b[0m \u001b[0mge\u001b[0m\u001b[0;34m.\u001b[0m\u001b[0mget_context\u001b[0m\u001b[0;34m(\u001b[0m\u001b[0;34m)\u001b[0m\u001b[0;34m\u001b[0m\u001b[0;34m\u001b[0m\u001b[0m\n\u001b[0m\u001b[1;32m      3\u001b[0m \u001b[0mdata\u001b[0m\u001b[0;34m\u001b[0m\u001b[0;34m\u001b[0m\u001b[0m\n",
      "\u001b[0;32m~/anaconda3/lib/python3.9/site-packages/great_expectations/util.py\u001b[0m in \u001b[0;36mget_context\u001b[0;34m()\u001b[0m\n\u001b[1;32m   1310\u001b[0m     \u001b[0;32mfrom\u001b[0m \u001b[0mgreat_expectations\u001b[0m\u001b[0;34m.\u001b[0m\u001b[0mdata_context\u001b[0m\u001b[0;34m.\u001b[0m\u001b[0mdata_context\u001b[0m \u001b[0;32mimport\u001b[0m \u001b[0mDataContext\u001b[0m\u001b[0;34m\u001b[0m\u001b[0;34m\u001b[0m\u001b[0m\n\u001b[1;32m   1311\u001b[0m \u001b[0;34m\u001b[0m\u001b[0m\n\u001b[0;32m-> 1312\u001b[0;31m     \u001b[0;32mreturn\u001b[0m \u001b[0mDataContext\u001b[0m\u001b[0;34m(\u001b[0m\u001b[0;34m)\u001b[0m\u001b[0;34m\u001b[0m\u001b[0;34m\u001b[0m\u001b[0m\n\u001b[0m\u001b[1;32m   1313\u001b[0m \u001b[0;34m\u001b[0m\u001b[0m\n\u001b[1;32m   1314\u001b[0m \u001b[0;34m\u001b[0m\u001b[0m\n",
      "\u001b[0;32m~/anaconda3/lib/python3.9/site-packages/great_expectations/data_context/data_context.py\u001b[0m in \u001b[0;36m__init__\u001b[0;34m(self, context_root_dir, runtime_environment, ge_cloud_mode, ge_cloud_base_url, ge_cloud_account_id, ge_cloud_access_token, ge_cloud_organization_id)\u001b[0m\n\u001b[1;32m   4199\u001b[0m             \u001b[0;31m# Determine the \"context root directory\" - this is the parent of \"great_expectations\" dir\u001b[0m\u001b[0;34m\u001b[0m\u001b[0;34m\u001b[0m\u001b[0m\n\u001b[1;32m   4200\u001b[0m             context_root_dir = (\n\u001b[0;32m-> 4201\u001b[0;31m                 \u001b[0mself\u001b[0m\u001b[0;34m.\u001b[0m\u001b[0mfind_context_root_dir\u001b[0m\u001b[0;34m(\u001b[0m\u001b[0;34m)\u001b[0m\u001b[0;34m\u001b[0m\u001b[0;34m\u001b[0m\u001b[0m\n\u001b[0m\u001b[1;32m   4202\u001b[0m                 \u001b[0;32mif\u001b[0m \u001b[0mcontext_root_dir\u001b[0m \u001b[0;32mis\u001b[0m \u001b[0;32mNone\u001b[0m\u001b[0;34m\u001b[0m\u001b[0;34m\u001b[0m\u001b[0m\n\u001b[1;32m   4203\u001b[0m                 \u001b[0;32melse\u001b[0m \u001b[0mcontext_root_dir\u001b[0m\u001b[0;34m\u001b[0m\u001b[0;34m\u001b[0m\u001b[0m\n",
      "\u001b[0;32m~/anaconda3/lib/python3.9/site-packages/great_expectations/data_context/data_context.py\u001b[0m in \u001b[0;36mfind_context_root_dir\u001b[0;34m(cls)\u001b[0m\n\u001b[1;32m   4348\u001b[0m \u001b[0;34m\u001b[0m\u001b[0m\n\u001b[1;32m   4349\u001b[0m         \u001b[0;32mif\u001b[0m \u001b[0mresult\u001b[0m \u001b[0;32mis\u001b[0m \u001b[0;32mNone\u001b[0m\u001b[0;34m:\u001b[0m\u001b[0;34m\u001b[0m\u001b[0;34m\u001b[0m\u001b[0m\n\u001b[0;32m-> 4350\u001b[0;31m             \u001b[0;32mraise\u001b[0m \u001b[0mge_exceptions\u001b[0m\u001b[0;34m.\u001b[0m\u001b[0mConfigNotFoundError\u001b[0m\u001b[0;34m(\u001b[0m\u001b[0;34m)\u001b[0m\u001b[0;34m\u001b[0m\u001b[0;34m\u001b[0m\u001b[0m\n\u001b[0m\u001b[1;32m   4351\u001b[0m \u001b[0;34m\u001b[0m\u001b[0m\n\u001b[1;32m   4352\u001b[0m         \u001b[0mlogger\u001b[0m\u001b[0;34m.\u001b[0m\u001b[0mdebug\u001b[0m\u001b[0;34m(\u001b[0m\u001b[0;34mf\"Using project config: {yml_path}\"\u001b[0m\u001b[0;34m)\u001b[0m\u001b[0;34m\u001b[0m\u001b[0;34m\u001b[0m\u001b[0m\n",
      "\u001b[0;31mConfigNotFoundError\u001b[0m: Error: No great_expectations directory was found here!\n    - Please check that you are in the correct directory or have specified the correct directory.\n    - If you have never run Great Expectations in this project, please run `great_expectations init` to get started.\n"
     ]
    }
   ],
   "source": [
    "import great_expectations as ge \n",
    "data  = ge.get_context()\n",
    "data"
   ]
  },
  {
   "cell_type": "code",
   "execution_count": null,
   "metadata": {},
   "outputs": [],
   "source": []
  }
 ],
 "metadata": {
  "interpreter": {
   "hash": "e0109ad4c837d8bfe4075949751f50026ce810972a48c112f1f00361f83e3686"
  },
  "kernelspec": {
   "display_name": "Python 3 (ipykernel)",
   "language": "python",
   "name": "python3"
  },
  "language_info": {
   "codemirror_mode": {
    "name": "ipython",
    "version": 3
   },
   "file_extension": ".py",
   "mimetype": "text/x-python",
   "name": "python",
   "nbconvert_exporter": "python",
   "pygments_lexer": "ipython3",
   "version": "3.9.7"
  }
 },
 "nbformat": 4,
 "nbformat_minor": 2
}
